<?xml version="1.0"?>
<robot name="homeplater">
    <material name="black">
        <color rgba="0 0 0 1"/>
    </material>
    <material name="purple">
        <color rgba="0.3098 0.1765 0.4980 1" />
    </material>
    <material name="gray">
        <color rgba="0.5 0.5 0.5 1" />
    </material>

    <link name="base_link">
        <visual>
            <geometry>
                <box size="0.16 0.16 0.005"/>
            </geometry>
            <material name="purple"/>
        </visual>
    </link>

    <joint name="caster joint" type="fixed">
        <parent link="base_link"/>
        <child link="caster"/>
        <origin xyz="-0.044 0 -0.0185" rpy="0.707 -0.707 -1.571"/>
    </joint>

    <link name="caster">
        <visual>
            <geometry>
                <sphere radius="0.014"/>
            </geometry>
            <material name="gray"/>
        </visual>
    </link>

    <joint name="left_wheel_joint" type="continuous">
        <parent link="base_link"/>
        <child link="left_wheel"/>
        <origin xyz="0.048 0.095 0" rpy="1.571 0 0"/>
        <axis xyz="0 0 1" />
    </joint>

    <link name="left_wheel">
        <visual>
            <geometry>
                <cylinder radius="0.0325" length="0.027"/>
            </geometry>
            <material name="black"/>
        </visual>
    </link>

    <joint name="right_wheel_joint" type="continuous">
        <parent link="base_link"/>
        <child link="right_wheel"/>
        <origin xyz="0.048 -0.095 0" rpy="1.571 0 0"/>
        <axis xyz="0 0 1" />
    </joint>

    <link name="right_wheel">
        <visual>
            <geometry>
                <cylinder radius="0.0325" length="0.027"/>
            </geometry>
            <material name="black"/>
        </visual>
    </link>
    
</robot>
